Workbook

Sheet PERT Сводка
A1: ID | B1: Фаза | C1: Название задачи | D1: Тип работы | E1: O_avg (дни) | F1: M_avg (дни) | G1: P_avg (дни) | H1: Te_avg (дни) | I1: Var (дни) | K1: Выводы
A2: 45658 | B2: Инициация и управление | C2: Определить цели и метрики успеха MVP | D2: Управление | E2: =ROUND(AVERAGE('PERT Тимур'!E2,'PERT Леша'!E2,'PERT Ева'!E2,'PERT Адам'!E2,'PERT Дима'!E2), 4) -> 0.8 | F2: =ROUND(AVERAGE('PERT Тимур'!F2,'PERT Леша'!F2,'PERT Ева'!F2,'PERT Адам'!F2,'PERT Дима'!F2), 4) -> 1.5 | G2: =ROUND(AVERAGE('PERT Тимур'!G2,'PERT Леша'!G2,'PERT Ева'!G2,'PERT Адам'!G2,'PERT Дима'!G2), 4) -> 2.4 | H2: =ROUND((E2+4*F2+G2)/6,2) -> 1.53 | I2: =ROUND(POW((G2 - E2) / 6,2), 4) -> 0.0711 | K2: Ожидаемая длительность (в днях) | L2: =ROUND(SUM(H2:H71) / L10, 2) -> 26.96
A3: 45689 | B3: Инициация и управление | C3: Определить Definition of Done для MVP | D3: Управление | E3: =ROUND(AVERAGE('PERT Тимур'!E3,'PERT Леша'!E3,'PERT Ева'!E3,'PERT Адам'!E3,'PERT Дима'!E3), 4) -> 0.7 | F3: =ROUND(AVERAGE('PERT Тимур'!F3,'PERT Леша'!F3,'PERT Ева'!F3,'PERT Адам'!F3,'PERT Дима'!F3), 4) -> 1.3 | G3: =ROUND(AVERAGE('PERT Тимур'!G3,'PERT Леша'!G3,'PERT Ева'!G3,'PERT Адам'!G3,'PERT Дима'!G3), 4) -> 2.3 | H3: =ROUND((E3+4*F3+G3)/6,2) -> 1.37 | I3: =ROUND(POW((G3 - E3) / 6,2), 4) -> 0.0711 | K3: Кол-во рабочих дней в месяце | L3: 20
A4: 45717 | B4: Инициация и управление | C4: Сформировать high-level roadmap релиза MVP | D4: Управление | E4: =ROUND(AVERAGE('PERT Тимур'!E4,'PERT Леша'!E4,'PERT Ева'!E4,'PERT Адам'!E4,'PERT Дима'!E4), 4) -> 0.9 | F4: =ROUND(AVERAGE('PERT Тимур'!F4,'PERT Леша'!F4,'PERT Ева'!F4,'PERT Адам'!F4,'PERT Дима'!F4), 4) -> 1.9 | G4: =ROUND(AVERAGE('PERT Тимур'!G4,'PERT Леша'!G4,'PERT Ева'!G4,'PERT Адам'!G4,'PERT Дима'!G4), 4) -> 3.2 | H4: =ROUND((E4+4*F4+G4)/6,2) -> 1.95 | I4: =ROUND(POW((G4 - E4) / 6,2), 4) -> 0.1469 | K4: Ожидаемая длительность (в месяцах) | L4: =ROUND(L2/L3, 2) -> 1.35
A5: 45748 | B5: Инициация и управление | C5: Определить состав команды и распределить роли | D5: Управление | E5: =ROUND(AVERAGE('PERT Тимур'!E5,'PERT Леша'!E5,'PERT Ева'!E5,'PERT Адам'!E5,'PERT Дима'!E5), 4) -> 0.6 | F5: =ROUND(AVERAGE('PERT Тимур'!F5,'PERT Леша'!F5,'PERT Ева'!F5,'PERT Адам'!F5,'PERT Дима'!F5), 4) -> 1.1 | G5: =ROUND(AVERAGE('PERT Тимур'!G5,'PERT Леша'!G5,'PERT Ева'!G5,'PERT Адам'!G5,'PERT Дима'!G5), 4) -> 1.9 | H5: =ROUND((E5+4*F5+G5)/6,2) -> 1.15 | I5: =ROUND(POW((G5 - E5) / 6,2), 4) -> 0.0469 | K5: * предполагается, что каждая задача выполняется одним исполнителем
A6: 45778 | B6: Инициация и управление | C6: Идентифицировать и описать ключевые риски проекта | D6: Управление | E6: =ROUND(AVERAGE('PERT Тимур'!E6,'PERT Леша'!E6,'PERT Ева'!E6,'PERT Адам'!E6,'PERT Дима'!E6), 4) -> 0.9 | F6: =ROUND(AVERAGE('PERT Тимур'!F6,'PERT Леша'!F6,'PERT Ева'!F6,'PERT Адам'!F6,'PERT Дима'!F6), 4) -> 1.7 | G6: =ROUND(AVERAGE('PERT Тимур'!G6,'PERT Леша'!G6,'PERT Ева'!G6,'PERT Адам'!G6,'PERT Дима'!G6), 4) -> 2.9 | H6: =ROUND((E6+4*F6+G6)/6,2) -> 1.77 | I6: =ROUND(POW((G6 - E6) / 6,2), 4) -> 0.1111
A7: 45809 | B7: Инициация и управление | C7: Настроить процесс управления задачами (доска, статусы, правила работы) | D7: Управление | E7: =ROUND(AVERAGE('PERT Тимур'!E7,'PERT Леша'!E7,'PERT Ева'!E7,'PERT Адам'!E7,'PERT Дима'!E7), 4) -> 1.1 | F7: =ROUND(AVERAGE('PERT Тимур'!F7,'PERT Леша'!F7,'PERT Ева'!F7,'PERT Адам'!F7,'PERT Дима'!F7), 4) -> 1.9 | G7: =ROUND(AVERAGE('PERT Тимур'!G7,'PERT Леша'!G7,'PERT Ева'!G7,'PERT Адам'!G7,'PERT Дима'!G7), 4) -> 3.2 | H7: =ROUND((E7+4*F7+G7)/6,2) -> 1.98 | I7: =ROUND(POW((G7 - E7) / 6,2), 4) -> 0.1225 | K7: Сумма дисперсий | L7: =SUM(I2:I71) -> 11.1171
A8: 45659 | B8: Требования и scope MVP | C8: Проанализировать аналоги и базовый функционал для уточнения scope | D8: Аналитика | E8: =ROUND(AVERAGE('PERT Тимур'!E8,'PERT Леша'!E8,'PERT Ева'!E8,'PERT Адам'!E8,'PERT Дима'!E8), 4) -> 1 | F8: =ROUND(AVERAGE('PERT Тимур'!F8,'PERT Леша'!F8,'PERT Ева'!F8,'PERT Адам'!F8,'PERT Дима'!F8), 4) -> 2 | G8: =ROUND(AVERAGE('PERT Тимур'!G8,'PERT Леша'!G8,'PERT Ева'!G8,'PERT Адам'!G8,'PERT Дима'!G8), 4) -> 3.7 | H8: =ROUND((E8+4*F8+G8)/6,2) -> 2.12 | I8: =ROUND(POW((G8 - E8) / 6,2), 4) -> 0.2025 | K8: Стандартное отклонение (в днях) | L8: =ROUND(SQRT(L7), 4) -> 3.3342
A9: 45690 | B9: Требования и scope MVP | C9: Сформировать список функциональных требований к MVP | D9: Аналитика | E9: =ROUND(AVERAGE('PERT Тимур'!E9,'PERT Леша'!E9,'PERT Ева'!E9,'PERT Адам'!E9,'PERT Дима'!E9), 4) -> 1 | F9: =ROUND(AVERAGE('PERT Тимур'!F9,'PERT Леша'!F9,'PERT Ева'!F9,'PERT Адам'!F9,'PERT Дима'!F9), 4) -> 2 | G9: =ROUND(AVERAGE('PERT Тимур'!G9,'PERT Леша'!G9,'PERT Ева'!G9,'PERT Адам'!G9,'PERT Дима'!G9), 4) -> 3.2 | H9: =ROUND((E9+4*F9+G9)/6,2) -> 2.03 | I9: =ROUND(POW((G9 - E9) / 6,2), 4) -> 0.1344
A10: 45718 | B10: Требования и scope MVP | C10: Сформировать список нефункциональных требований (время ответа, платформы, лимиты) | D10: Аналитика | E10: =ROUND(AVERAGE('PERT Тимур'!E10,'PERT Леша'!E10,'PERT Ева'!E10,'PERT Адам'!E10,'PERT Дима'!E10), 4) -> 0.9 | F10: =ROUND(AVERAGE('PERT Тимур'!F10,'PERT Леша'!F10,'PERT Ева'!F10,'PERT Адам'!F10,'PERT Дима'!F10), 4) -> 1.7 | G10: =ROUND(AVERAGE('PERT Тимур'!G10,'PERT Леша'!G10,'PERT Ева'!G10,'PERT Адам'!G10,'PERT Дима'!G10), 4) -> 2.8 | H10: =ROUND((E10+4*F10+G10)/6,2) -> 1.75 | I10: =ROUND(POW((G10 - E10) / 6,2), 4) -> 0.1003 | K10: Количество людей в команде | L10: 5
A11: 45749 | B11: Требования и scope MVP | C11: Зафиксировать список того, что не входит в MVP | D11: Аналитика | E11: =ROUND(AVERAGE('PERT Тимур'!E11,'PERT Леша'!E11,'PERT Ева'!E11,'PERT Адам'!E11,'PERT Дима'!E11), 4) -> 0.6 | F11: =ROUND(AVERAGE('PERT Тимур'!F11,'PERT Леша'!F11,'PERT Ева'!F11,'PERT Адам'!F11,'PERT Дима'!F11), 4) -> 0.9 | G11: =ROUND(AVERAGE('PERT Тимур'!G11,'PERT Леша'!G11,'PERT Ева'!G11,'PERT Адам'!G11,'PERT Дима'!G11), 4) -> 1.6 | H11: =ROUND((E11+4*F11+G11)/6,2) -> 0.97 | I11: =ROUND(POW((G11 - E11) / 6,2), 4) -> 0.0278
A12: 45779 | B12: Требования и scope MVP | C12: Описать сценарий «распознать фильм по одному фото» в виде спецификации | D12: Аналитика | E12: =ROUND(AVERAGE('PERT Тимур'!E12,'PERT Леша'!E12,'PERT Ева'!E12,'PERT Адам'!E12,'PERT Дима'!E12), 4) -> 1.2 | F12: =ROUND(AVERAGE('PERT Тимур'!F12,'PERT Леша'!F12,'PERT Ева'!F12,'PERT Адам'!F12,'PERT Дима'!F12), 4) -> 2.1 | G12: =ROUND(AVERAGE('PERT Тимур'!G12,'PERT Леша'!G12,'PERT Ева'!G12,'PERT Адам'!G12,'PERT Дима'!G12), 4) -> 3.5 | H12: =ROUND((E12+4*F12+G12)/6,2) -> 2.18 | I12: =ROUND(POW((G12 - E12) / 6,2), 4) -> 0.1469
A13: 45810 | B13: Требования и scope MVP | C13: Описать сценарии работы с лимитами free-tier и превышения лимита | D13: Аналитика | E13: =ROUND(AVERAGE('PERT Тимур'!E13,'PERT Леша'!E13,'PERT Ева'!E13,'PERT Адам'!E13,'PERT Дима'!E13), 4) -> 0.7 | F13: =ROUND(AVERAGE('PERT Тимур'!F13,'PERT Леша'!F13,'PERT Ева'!F13,'PERT Адам'!F13,'PERT Дима'!F13), 4) -> 1.3 | G13: =ROUND(AVERAGE('PERT Тимур'!G13,'PERT Леша'!G13,'PERT Ева'!G13,'PERT Адам'!G13,'PERT Дима'!G13), 4) -> 2.3 | H13: =ROUND((E13+4*F13+G13)/6,2) -> 1.37 | I13: =ROUND(POW((G13 - E13) / 6,2), 4) -> 0.0711
A14: 45840 | B14: Требования и scope MVP | C14: Утвердить документ требований MVP внутри команды | D14: Управление | E14: =ROUND(AVERAGE('PERT Тимур'!E14,'PERT Леша'!E14,'PERT Ева'!E14,'PERT Адам'!E14,'PERT Дима'!E14), 4) -> 0.9 | F14: =ROUND(AVERAGE('PERT Тимур'!F14,'PERT Леша'!F14,'PERT Ева'!F14,'PERT Адам'!F14,'PERT Дима'!F14), 4) -> 1.5 | G14: =ROUND(AVERAGE('PERT Тимур'!G14,'PERT Леша'!G14,'PERT Ева'!G14,'PERT Адам'!G14,'PERT Дима'!G14), 4) -> 2.5 | H14: =ROUND((E14+4*F14+G14)/6,2) -> 1.57 | I14: =ROUND(POW((G14 - E14) / 6,2), 4) -> 0.0711
A15: 45660 | B15: UX / UI и сценарии | C15: Определить пользовательские роли и ключевые сценарии использования | D15: UX/UI | E15: =ROUND(AVERAGE('PERT Тимур'!E15,'PERT Леша'!E15,'PERT Ева'!E15,'PERT Адам'!E15,'PERT Дима'!E15), 4) -> 0.7 | F15: =ROUND(AVERAGE('PERT Тимур'!F15,'PERT Леша'!F15,'PERT Ева'!F15,'PERT Адам'!F15,'PERT Дима'!F15), 4) -> 1.4 | G15: =ROUND(AVERAGE('PERT Тимур'!G15,'PERT Леша'!G15,'PERT Ева'!G15,'PERT Адам'!G15,'PERT Дима'!G15), 4) -> 2.6 | H15: =ROUND((E15+4*F15+G15)/6,2) -> 1.48 | I15: =ROUND(POW((G15 - E15) / 6,2), 4) -> 0.1003
A16: 45691 | B16: UX / UI и сценарии | C16: Построить пользовательский поток распознавания фильма по фото | D16: UX/UI | E16: =ROUND(AVERAGE('PERT Тимур'!E16,'PERT Леша'!E16,'PERT Ева'!E16,'PERT Адам'!E16,'PERT Дима'!E16), 4) -> 0.7 | F16: =ROUND(AVERAGE('PERT Тимур'!F16,'PERT Леша'!F16,'PERT Ева'!F16,'PERT Адам'!F16,'PERT Дима'!F16), 4) -> 1.6 | G16: =ROUND(AVERAGE('PERT Тимур'!G16,'PERT Леша'!G16,'PERT Ева'!G16,'PERT Адам'!G16,'PERT Дима'!G16), 4) -> 2.8 | H16: =ROUND((E16+4*F16+G16)/6,2) -> 1.65 | I16: =ROUND(POW((G16 - E16) / 6,2), 4) -> 0.1225
A17: 45719 | B17: UX / UI и сценарии | C17: Построить пользовательский поток просмотра истории запросов | D17: UX/UI | E17: =ROUND(AVERAGE('PERT Тимур'!E17,'PERT Леша'!E17,'PERT Ева'!E17,'PERT Адам'!E17,'PERT Дима'!E17), 4) -> 0.6 | F17: =ROUND(AVERAGE('PERT Тимур'!F17,'PERT Леша'!F17,'PERT Ева'!F17,'PERT Адам'!F17,'PERT Дима'!F17), 4) -> 1.1 | G17: =ROUND(AVERAGE('PERT Тимур'!G17,'PERT Леша'!G17,'PERT Ева'!G17,'PERT Адам'!G17,'PERT Дима'!G17), 4) -> 2.1 | H17: =ROUND((E17+4*F17+G17)/6,2) -> 1.18 | I17: =ROUND(POW((G17 - E17) / 6,2), 4) -> 0.0625
A18: 45750 | B18: UX / UI и сценарии | C18: Спроектировать UX обработки ошибок (нет сети, плохое фото, фильм не найден) | D18: UX/UI | E18: =ROUND(AVERAGE('PERT Тимур'!E18,'PERT Леша'!E18,'PERT Ева'!E18,'PERT Адам'!E18,'PERT Дима'!E18), 4) -> 0.8 | F18: =ROUND(AVERAGE('PERT Тимур'!F18,'PERT Леша'!F18,'PERT Ева'!F18,'PERT Адам'!F18,'PERT Дима'!F18), 4) -> 1.5 | G18: =ROUND(AVERAGE('PERT Тимур'!G18,'PERT Леша'!G18,'PERT Ева'!G18,'PERT Адам'!G18,'PERT Дима'!G18), 4) -> 2.5 | H18: =ROUND((E18+4*F18+G18)/6,2) -> 1.55 | I18: =ROUND(POW((G18 - E18) / 6,2), 4) -> 0.0803
A19: 45780 | B19: UX / UI и сценарии | C19: Подготовить wireframes стартового экрана и экрана загрузки фото | D19: UX/UI | E19: =ROUND(AVERAGE('PERT Тимур'!E19,'PERT Леша'!E19,'PERT Ева'!E19,'PERT Адам'!E19,'PERT Дима'!E19), 4) -> 0.9 | F19: =ROUND(AVERAGE('PERT Тимур'!F19,'PERT Леша'!F19,'PERT Ева'!F19,'PERT Адам'!F19,'PERT Дима'!F19), 4) -> 1.7 | G19: =ROUND(AVERAGE('PERT Тимур'!G19,'PERT Леша'!G19,'PERT Ева'!G19,'PERT Адам'!G19,'PERT Дима'!G19), 4) -> 2.8 | H19: =ROUND((E19+4*F19+G19)/6,2) -> 1.75 | I19: =ROUND(POW((G19 - E19) / 6,2), 4) -> 0.1003
A20: 45811 | B20: UX / UI и сценарии | C20: Подготовить wireframes экрана результата и экрана истории запросов | D20: UX/UI | E20: =ROUND(AVERAGE('PERT Тимур'!E20,'PERT Леша'!E20,'PERT Ева'!E20,'PERT Адам'!E20,'PERT Дима'!E20), 4) -> 1 | F20: =ROUND(AVERAGE('PERT Тимур'!F20,'PERT Леша'!F20,'PERT Ева'!F20,'PERT Адам'!F20,'PERT Дима'!F20), 4) -> 1.9 | G20: =ROUND(AVERAGE('PERT Тимур'!G20,'PERT Леша'!G20,'PERT Ева'!G20,'PERT Адам'!G20,'PERT Дима'!G20), 4) -> 3 | H20: =ROUND((E20+4*F20+G20)/6,2) -> 1.93 | I20: =ROUND(POW((G20 - E20) / 6,2), 4) -> 0.1111
A21: 45841 | B21: UX / UI и сценарии | C21: Подготовить wireframes экрана логина/регистрации и экрана лимитов | D21: UX/UI | E21: =ROUND(AVERAGE('PERT Тимур'!E21,'PERT Леша'!E21,'PERT Ева'!E21,'PERT Адам'!E21,'PERT Дима'!E21), 4) -> 1 | F21: =ROUND(AVERAGE('PERT Тимур'!F21,'PERT Леша'!F21,'PERT Ева'!F21,'PERT Адам'!F21,'PERT Дима'!F21), 4) -> 1.7 | G21: =ROUND(AVERAGE('PERT Тимур'!G21,'PERT Леша'!G21,'PERT Ева'!G21,'PERT Адам'!G21,'PERT Дима'!G21), 4) -> 2.8 | H21: =ROUND((E21+4*F21+G21)/6,2) -> 1.77 | I21: =ROUND(POW((G21 - E21) / 6,2), 4) -> 0.09
A22: 45872 | B22: UX / UI и сценарии | C22: Провести внутреннее UX-ревью и финализировать UX-спецификацию | D22: UX/UI | E22: =ROUND(AVERAGE('PERT Тимур'!E22,'PERT Леша'!E22,'PERT Ева'!E22,'PERT Адам'!E22,'PERT Дима'!E22), 4) -> 0.9 | F22: =ROUND(AVERAGE('PERT Тимур'!F22,'PERT Леша'!F22,'PERT Ева'!F22,'PERT Адам'!F22,'PERT Дима'!F22), 4) -> 1.7 | G22: =ROUND(AVERAGE('PERT Тимур'!G22,'PERT Леша'!G22,'PERT Ева'!G22,'PERT Адам'!G22,'PERT Дима'!G22), 4) -> 2.5 | H22: =ROUND((E22+4*F22+G22)/6,2) -> 1.7 | I22: =ROUND(POW((G22 - E22) / 6,2), 4) -> 0.0711
... A71: 45908 | B71: Тестирование, релиз и поддержка | C71: Составить план пострелизной поддержки и список известных ограничений MVP | D71: Управление | E71: =ROUND(AVERAGE('PERT Тимур'!E71,'PERT Леша'!E71,'PERT Ева'!E71,'PERT Адам'!E71,'PERT Дима'!E71), 4) -> 0.8 | F71: =ROUND(AVERAGE('PERT Тимур'!F71,'PERT Леша'!F71,'PERT Ева'!F71,'PERT Адам'!F71,'PERT Дима'!F71), 4) -> 1.3 | G71: =ROUND(AVERAGE('PERT Тимур'!G71,'PERT Леша'!G71,'PERT Ева'!G71,'PERT Адам'!G71,'PERT Дима'!G71), 4) -> 2.3 | H71: =ROUND((E71+4*F71+G71)/6,2) -> 1.38 | I71: =ROUND(POW((G71 - E71) / 6,2), 4) -> 0.0625

Sheet PERT Тимур
A1: ID | B1: Фаза | C1: Название задачи | D1: Тип работы | E1: O (дни) | F1: M (дни) | G1: P (дни)
A2: 45658 | B2: Инициация и управление | C2: Определить цели и метрики успеха MVP | D2: Управление | E2: 0.5 | F2: 1 | G2: 2
A3: 45689 | B3: Инициация и управление | C3: Определить Definition of Done для MVP | D3: Управление | E3: 0.5 | F3: 1 | G3: 1.5
A4: 45717 | B4: Инициация и управление | C4: Сформировать high-level roadmap релиза MVP | D4: Управление | E4: 0.5 | F4: 1 | G4: 2
A5: 45748 | B5: Инициация и управление | C5: Определить состав команды и распределить роли | D5: Управление | E5: 0.5 | F5: 0.5 | G5: 1
A6: 45778 | B6: Инициация и управление | C6: Идентифицировать и описать ключевые риски проекта | D6: Управление | E6: 0.5 | F6: 1 | G6: 1.5
A7: 45809 | B7: Инициация и управление | C7: Настроить процесс управления задачами (доска, статусы, правила работы) | D7: Управление | E7: 0.5 | F7: 1 | G7: 2
A8: 45659 | B8: Требования и scope MVP | C8: Проанализировать аналоги и базовый функционал для уточнения scope | D8: Аналитика | E8: 0.5 | F8: 1 | G8: 2
A9: 45690 | B9: Требования и scope MVP | C9: Сформировать список функциональных требований к MVP | D9: Аналитика | E9: 0.5 | F9: 1 | G9: 2
A10: 45718 | B10: Требования и scope MVP | C10: Сформировать список нефункциональных требований (время ответа, платформы, лимиты) | D10: Аналитика | E10: 0.5 | F10: 0.5 | G10: 1
A11: 45749 | B11: Требования и scope MVP | C11: Зафиксировать список того, что не входит в MVP | D11: Аналитика | E11: 0.5 | F11: 0.5 | G11: 1
A12: 45779 | B12: Требования и scope MVP | C12: Описать сценарий «распознать фильм по одному фото» в виде спецификации | D12: Аналитика | E12: 0.5 | F12: 1 | G12: 1.5
A13: 45810 | B13: Требования и scope MVP | C13: Описать сценарии работы с лимитами free-tier и превышения лимита | D13: Аналитика | E13: 0.5 | F13: 1 | G13: 1.5
... A71: 45908 | B71: Тестирование, релиз и поддержка | C71: Составить план пострелизной поддержки и список известных ограничений MVP | D71: Управление | E71: 0.5 | F71: 0.5 | G71: 1

Sheet PERT Леша
A1: ID | B1: Фаза | C1: Название задачи | D1: Тип работы | E1: O (дни) | F1: M (дни) | G1: P (дни)
A2: 45658 | B2: Инициация и управление | C2: Определить цели и метрики успеха MVP | D2: Управление | E2: 1 | F2: 2 | G2: 3
A3: 45689 | B3: Инициация и управление | C3: Определить Definition of Done для MVP | D3: Управление | E3: 0.5 | F3: 1 | G3: 2
A4: 45717 | B4: Инициация и управление | C4: Сформировать high-level roadmap релиза MVP | D4: Управление | E4: 1 | F4: 2 | G4: 3
A5: 45748 | B5: Инициация и управление | C5: Определить состав команды и распределить роли | D5: Управление | E5: 0.5 | F5: 1 | G5: 2
A6: 45778 | B6: Инициация и управление | C6: Идентифицировать и описать ключевые риски проекта | D6: Управление | E6: 1 | F6: 2 | G6: 3
A7: 45809 | B7: Инициация и управление | C7: Настроить процесс управления задачами (доска, статусы, правила работы) | D7: Управление | E7: 1 | F7: 2 | G7: 3
A8: 45659 | B8: Требования и scope MVP | C8: Проанализировать аналоги и базовый функционал для уточнения scope | D8: Аналитика | E8: 1 | F8: 2 | G8: 4
A9: 45690 | B9: Требования и scope MVP | C9: Сформировать список функциональных требований к MVP | D9: Аналитика | E9: 1 | F9: 1.5 | G9: 2
A10: 45718 | B10: Требования и scope MVP | C10: Сформировать список нефункциональных требований (время ответа, платформы, лимиты) | D10: Аналитика | E10: 1 | F10: 1.5 | G10: 2
A11: 45749 | B11: Требования и scope MVP | C11: Зафиксировать список того, что не входит в MVP | D11: Аналитика | E11: 0.5 | F11: 1 | G11: 1.5
A12: 45779 | B12: Требования и scope MVP | C12: Описать сценарий «распознать фильм по одному фото» в виде спецификации | D12: Аналитика | E12: 1.5 | F12: 2 | G12: 4
A13: 45810 | B13: Требования и scope MVP | C13: Описать сценарии работы с лимитами free-tier и превышения лимита | D13: Аналитика | E13: 0.5 | F13: 1 | G13: 2
... A71: 45908 | B71: Тестирование, релиз и поддержка | C71: Составить план пострелизной поддержки и список известных ограничений MVP | D71: Управление | E71: 1 | F71: 1.5 | G71: 2.5

Sheet PERT Ева
A1: ID | B1: Фаза | C1: Название задачи | D1: Тип работы | E1: O (дни) | F1: M (дни) | G1: P (дни)
A2: 45658 | B2: Инициация и управление | C2: Определить цели и метрики успеха MVP | D2: Управление | E2: 1 | F2: 1.5 | G2: 2
A3: 45689 | B3: Инициация и управление | C3: Определить Definition of Done для MVP | D3: Управление | E3: 1 | F3: 1.5 | G3: 2
A4: 45717 | B4: Инициация и управление | C4: Сформировать high-level roadmap релиза MVP | D4: Управление | E4: 1 | F4: 1.5 | G4: 2
A5: 45748 | B5: Инициация и управление | C5: Определить состав команды и распределить роли | D5: Управление | E5: 0.5 | F5: 1 | G5: 1.5
A6: 45778 | B6: Инициация и управление | C6: Идентифицировать и описать ключевые риски проекта | D6: Управление | E6: 1 | F6: 1.5 | G6: 2
A7: 45809 | B7: Инициация и управление | C7: Настроить процесс управления задачами (доска, статусы, правила работы) | D7: Управление | E7: 1 | F7: 1.5 | G7: 2
A8: 45659 | B8: Требования и scope MVP | C8: Проанализировать аналоги и базовый функционал для уточнения scope | D8: Аналитика | E8: 0.5 | F8: 1 | G8: 1.5
A9: 45690 | B9: Требования и scope MVP | C9: Сформировать список функциональных требований к MVP | D9: Аналитика | E9: 1 | F9: 1.5 | G9: 2
A10: 45718 | B10: Требования и scope MVP | C10: Сформировать список нефункциональных требований (время ответа, платформы, лимиты) | D10: Аналитика | E10: 1 | F10: 1.5 | G10: 2
A11: 45749 | B11: Требования и scope MVP | C11: Зафиксировать список того, что не входит в MVP | D11: Аналитика | E11: 0.5 | F11: 1 | G11: 1.5
A12: 45779 | B12: Требования и scope MVP | C12: Описать сценарий «распознать фильм по одному фото» в виде спецификации | D12: Аналитика | E12: 1 | F12: 1.5 | G12: 2
A13: 45810 | B13: Требования и scope MVP | C13: Описать сценарии работы с лимитами free-tier и превышения лимита | D13: Аналитика | E13: 1 | F13: 1.5 | G13: 2
... A71: 45908 | B71: Тестирование, релиз и поддержка | C71: Составить план пострелизной поддержки и список известных ограничений MVP | D71: Управление | E71: 1 | F71: 1.5 | G71: 2

Sheet PERT Адам
A1: ID | B1: Фаза | C1: Название задачи | D1: Тип работы | E1: O (дни) | F1: M (дни) | G1: P (дни)
A2: 45658 | B2: Инициация и управление | C2: Определить цели и метрики успеха MVP | D2: Управление | E2: 0.5 | F2: 1 | G2: 2
A3: 45689 | B3: Инициация и управление | C3: Определить Definition of Done для MVP | D3: Управление | E3: 0.5 | F3: 1 | G3: 2
A4: 45717 | B4: Инициация и управление | C4: Сформировать high-level roadmap релиза MVP | D4: Управление | E4: 1 | F4: 2 | G4: 4
A5: 45748 | B5: Инициация и управление | C5: Определить состав команды и распределить роли | D5: Управление | E5: 0.5 | F5: 1 | G5: 2
A6: 45778 | B6: Инициация и управление | C6: Идентифицировать и описать ключевые риски проекта | D6: Управление | E6: 1 | F6: 2 | G6: 3
A7: 45809 | B7: Инициация и управление | C7: Настроить процесс управления задачами (доска, статусы, правила работы) | D7: Управление | E7: 2 | F7: 3 | G7: 5
A8: 45659 | B8: Требования и scope MVP | C8: Проанализировать аналоги и базовый функционал для уточнения scope | D8: Аналитика | E8: 1 | F8: 2 | G8: 4
A9: 45690 | B9: Требования и scope MVP | C9: Сформировать список функциональных требований к MVP | D9: Аналитика | E9: 0.5 | F9: 1 | G9: 2
A10: 45718 | B10: Требования и scope MVP | C10: Сформировать список нефункциональных требований (время ответа, платформы, лимиты) | D10: Аналитика | E10: 1 | F10: 2 | G10: 3
A11: 45749 | B11: Требования и scope MVP | C11: Зафиксировать список того, что не входит в MVP | D11: Аналитика | E11: 0.5 | F11: 1 | G11: 2
A12: 45779 | B12: Требования и scope MVP | C12: Описать сценарий «распознать фильм по одному фото» в виде спецификации | D12: Аналитика | E12: 2 | F12: 4 | G12: 6
A13: 45810 | B13: Требования и scope MVP | C13: Описать сценарии работы с лимитами free-tier и превышения лимита | D13: Аналитика | E13: 0.5 | F13: 1 | G13: 2
... A71: 45908 | B71: Тестирование, релиз и поддержка | C71: Составить план пострелизной поддержки и список известных ограничений MVP | D71: Управление | E71: 0.5 | F71: 1 | G71: 2

Sheet PERT Дима
A1: ID | B1: Фаза | C1: Название задачи | D1: Тип работы | E1: O (дни) | F1: M (дни) | G1: P (дни)
A2: 45658 | B2: Инициация и управление | C2: Определить цели и метрики успеха MVP | D2: Управление | E2: 1 | F2: 2 | G2: 3
A3: 45689 | B3: Инициация и управление | C3: Определить Definition of Done для MVP | D3: Управление | E3: 1 | F3: 2 | G3: 4
A4: 45717 | B4: Инициация и управление | C4: Сформировать high-level roadmap релиза MVP | D4: Управление | E4: 1 | F4: 3 | G4: 5
A5: 45748 | B5: Инициация и управление | C5: Определить состав команды и распределить роли | D5: Управление | E5: 1 | F5: 2 | G5: 3
A6: 45778 | B6: Инициация и управление | C6: Идентифицировать и описать ключевые риски проекта | D6: Управление | E6: 1 | F6: 2 | G6: 5
A7: 45809 | B7: Инициация и управление | C7: Настроить процесс управления задачами (доска, статусы, правила работы) | D7: Управление | E7: 1 | F7: 2 | G7: 4
A8: 45659 | B8: Требования и scope MVP | C8: Проанализировать аналоги и базовый функционал для уточнения scope | D8: Аналитика | E8: 2 | F8: 4 | G8: 7
A9: 45690 | B9: Требования и scope MVP | C9: Сформировать список функциональных требований к MVP | D9: Аналитика | E9: 2 | F9: 5 | G9: 8
A10: 45718 | B10: Требования и scope MVP | C10: Сформировать список нефункциональных требований (время ответа, платформы, лимиты) | D10: Аналитика | E10: 1 | F10: 3 | G10: 6
A11: 45749 | B11: Требования и scope MVP | C11: Зафиксировать список того, что не входит в MVP | D11: Аналитика | E11: 1 | F11: 1 | G11: 2
A12: 45779 | B12: Требования и scope MVP | C12: Описать сценарий «распознать фильм по одному фото» в виде спецификации | D12: Аналитика | E12: 1 | F12: 2 | G12: 4
A13: 45810 | B13: Требования и scope MVP | C13: Описать сценарии работы с лимитами free-tier и превышения лимита | D13: Аналитика | E13: 1 | F13: 2 | G13: 4
... A71: 45908 | B71: Тестирование, релиз и поддержка | C71: Составить план пострелизной поддержки и список известных ограничений MVP | D71: Управление | E71: 1 | F71: 2 | G71: 4

Sheet PERT Шаблон
A1: ID | B1: Фаза | C1: Название задачи | D1: Тип работы | E1: O (дни) | F1: M (дни) | G1: P (дни)
A2: 45658 | B2: Инициация и управление | C2: Определить цели и метрики успеха MVP | D2: Управление
A3: 45689 | B3: Инициация и управление | C3: Определить Definition of Done для MVP | D3: Управление
A4: 45717 | B4: Инициация и управление | C4: Сформировать high-level roadmap релиза MVP | D4: Управление
A5: 45748 | B5: Инициация и управление | C5: Определить состав команды и распределить роли | D5: Управление
A6: 45778 | B6: Инициация и управление | C6: Идентифицировать и описать ключевые риски проекта | D6: Управление
A7: 45809 | B7: Инициация и управление | C7: Настроить процесс управления задачами (доска, статусы, правила работы) | D7: Управление
A8: 45659 | B8: Требования и scope MVP | C8: Проанализировать аналоги и базовый функционал для уточнения scope | D8: Аналитика
A9: 45690 | B9: Требования и scope MVP | C9: Сформировать список функциональных требований к MVP | D9: Аналитика
A10: 45718 | B10: Требования и scope MVP | C10: Сформировать список нефункциональных требований (время ответа, платформы, лимиты) | D10: Аналитика
A11: 45749 | B11: Требования и scope MVP | C11: Зафиксировать список того, что не входит в MVP | D11: Аналитика
A12: 45779 | B12: Требования и scope MVP | C12: Описать сценарий «распознать фильм по одному фото» в виде спецификации | D12: Аналитика
A13: 45810 | B13: Требования и scope MVP | C13: Описать сценарии работы с лимитами free-tier и превышения лимита | D13: Аналитика
... A71: 45908 | B71: Тестирование, релиз и поддержка | C71: Составить план пострелизной поддержки и список известных ограничений MVP | D71: Управление

Sheet Use cases
A2: ID | B2: UC_Name | C2: Category | D2: Weight
A3: UC1 | B3: Запустить_приложение | C3: Simple | D3: 5
A4: UC2 | B4: Просмотреть_лимиты_free-tier | C4: Medium | D4: 10
A5: UC3 | B5: Выйти_из_аккаунта | C5: Simple | D5: 5
A6: UC4 | B6: Зарегистрироваться | C6: Medium | D6: 10
A7: UC5 | B7: Войти_в_систему | C7: Medium | D7: 10
A8: UC6 | B8: Сделать_фото | C8: Complex | D8: 15
A9: UC7 | B9: Выбрать_фото_из_галереи | C9: Complex | D9: 15
A10: UC8 | B10: Просмотреть_результат | C10: Complex | D10: 15
A11: UC9 | B11: Просмотреть_историю | C11: Complex | D11: 15
A12: UC10 | B12: Открыть_запись_из_истории | C12: Medium | D12: 10
A13: UC11 | B13: Распознать_фильм_по_фото | C13: Very_Complex | D13: 25
D14: =SUM(D3:D13) -> 135 | E14: TOTAL
D15: =D14 * 1.3 -> 175.5 | E15: TOTAL_with_risk
D16: 5 | E16: Team_Size
D17: =D15/D16 -> 35.1 | E17: Duration_days
D18: =D17/20 -> 1.755 | E18: Duration_months

Sheet Таблица для Gant
A1: Номер | B1: ID | C1: Фаза | D1: Название задачи | E1: Роль | F1: Длительность_дни
A2: 1 | B2: 45658 | C2: Инициация и управление | D2: Определить цели и метрики успеха MVP | E2: PM/Product | F2: 1.53
A3: 2 | B3: 45689 | C3: Инициация и управление | D3: Определить Definition of Done для MVP | E3: PM/Product | F3: 1.37
A4: 3 | B4: 45717 | C4: Инициация и управление | D4: Сформировать high-level roadmap релиза MVP | E4: PM/Product | F4: 1.95
A5: 4 | B5: 45748 | C5: Инициация и управление | D5: Определить состав команды и распределить роли | E5: PM/Product | F5: 1.15
A6: 5 | B6: 45778 | C6: Инициация и управление | D6: Идентифицировать и описать ключевые риски проекта | E6: PM/Product | F6: 1.77
A7: 6 | B7: 45809 | C7: Инициация и управление | D7: Настроить процесс управления задачами (доска, статусы, правила работы) | E7: PM/Product | F7: 1.98
A8: 7 | B8: 45659 | C8: Требования и scope MVP | D8: Проанализировать аналоги и базовый функционал для уточнения scope | E8: PM/BA | F8: 2.12
A9: 8 | B9: 45690 | C9: Требования и scope MVP | D9: Сформировать список функциональных требований к MVP | E9: PM/BA | F9: 2.03
A10: 9 | B10: 45718 | C10: Требования и scope MVP | D10: Сформировать список нефункциональных требований (время ответа, платформы, лимиты) | E10: PM/BA | F10: 1.75
A11: 10 | B11: 45749 | C11: Требования и scope MVP | D11: Зафиксировать список того, что не входит в MVP | E11: PM/BA | F11: 0.97
A12: 11 | B12: 45779 | C12: Требования и scope MVP | D12: Описать сценарий «распознать фильм по одному фото» в виде спецификации | E12: PM/BA | F12: 2.18
A13: 12 | B13: 45810 | C13: Требования и scope MVP | D13: Описать сценарии работы с лимитами free-tier и превышения лимита | E13: PM/BA | F13: 1.37
... A71: 70 | B71: 45908 | C71: Тестирование, релиз и поддержка | D71: Составить план пострелизной поддержки и список известных ограничений MVP | E71: PM/Product | F71: 1.38

Sheet Диаграмма Ганта
J2: Cоздайте диаграмму Ганта в GanttPRO всего в несколько кликов
A4: Frame Finder _ HW-5 | L4: 45994
A5: Цвет | B5: Структура задач | C5: Наименование задач | D5: Исполнитель | E5: Дата начала | F5: Дата окончания | G5: Крайний срок | H5: Прогресс (%) | I5: Длительность (часы) | J5: Трудозатраты в часах | K5: Затраченное время (минуты) | L5: Статус | M5: Приоритет | N5: Описание задачи | O5: Предшественник | P5: Стоимость | Q5: Фактическая стоимость | R5: Создан | S5: Создатель | T5: Тип | U5: Проект | V5: Уровень
B6: 1 | C6: Определить цели и метрики успеха MVP | D6: Product Manager | E6: 45995 | F6: 45996 | H6: 0 | I6: 12.25 | J6: 12.25 | K6: 0 | L6: Открыт | M6: Средний | N6: Инициация и управление | P6: 0 | Q6: 0 | R6: 45994 | S6: Timur Byurchiev | T6: задача | U6: Frame Finder _ HW-5 | V6: 1
B7: 2 | C7: Определить Definition of Done для MVP | D7: Product Manager | E7: 45996 | F7: 46000 | H7: 0 | I7: 10.97 | J7: 10.97 | K7: 0 | L7: Открыт | M7: Средний | N7: Инициация и управление | O7: 1 | P7: 0 | Q7: 0 | R7: 45994 | S7: Timur Byurchiev | T7: задача | U7: Frame Finder _ HW-5 | V7: 1
B8: 3 | C8: Сформировать high-level roadmap релиза MVP | D8: Product Manager | E8: 46000 | F8: 46002 | H8: 0 | I8: 15.6 | J8: 15.6 | K8: 0 | L8: Открыт | M8: Средний | N8: Инициация и управление | O8: 2 | P8: 0 | Q8: 0 | R8: 45994 | S8: Timur Byurchiev | T8: задача | U8: Frame Finder _ HW-5 | V8: 1
B9: 4 | C9: Определить состав команды и распределить роли | D9: Product Manager | E9: 46002 | F9: 46003 | H9: 0 | I9: 9.2 | J9: 9.2 | K9: 0 | L9: Открыт | M9: Средний | N9: Инициация и управление | O9: 3 | P9: 0 | Q9: 0 | R9: 45994 | S9: Timur Byurchiev | T9: задача | U9: Frame Finder _ HW-5 | V9: 1
B10: 5 | C10: Идентифицировать и описать ключевые риски проекта | D10: Product Manager | E10: 46003 | F10: 46007 | H10: 0 | I10: 14.17 | J10: 14.17 | K10: 0 | L10: Открыт | M10: Средний | N10: Инициация и управление | O10: 4 | P10: 0 | Q10: 0 | R10: 45994 | S10: Timur Byurchiev | T10: задача | U10: Frame Finder _ HW-5 | V10: 1
B11: 6 | C11: Настроить процесс управления задачами (доска, статусы, правила работы) | D11: Product Manager | E11: 46007 | F11: 46009 | H11: 0 | I11: 15.85 | J11: 15.85 | K11: 0 | L11: Открыт | M11: Средний | N11: Инициация и управление | O11: 5 | P11: 0 | Q11: 0 | R11: 45994 | S11: Timur Byurchiev | T11: задача | U11: Frame Finder _ HW-5 | V11: 1
B12: 7 | C12: Проанализировать аналоги и базовый функционал для уточнения scope | D12: Product Manager, Business Analyst | E12: 46009 | F12: 46013 | H12: 0 | I12: 16.97 | J12: 16.97 | K12: 0 | L12: Открыт | M12: Средний | N12: Требования и scope MVP | O12: 6 | P12: 0 | Q12: 0 | R12: 45994 | S12: Timur Byurchiev | T12: задача | U12: Frame Finder _ HW-5 | V12: 1
B13: 8 | C13: Сформировать список функциональных требований к MVP | D13: Product Manager, Business Analyst | E13: 46013 | F13: 46015 | H13: 0 | I13: 16.25 | J13: 16.25 | K13: 0 | L13: Открыт | M13: Средний | N13: Требования и scope MVP | O13: 7 | P13: 0 | Q13: 0 | R13: 45994 | S13: Timur Byurchiev | T13: задача | U13: Frame Finder _ HW-5 | V13: 1
B14: 9 | C14: Сформировать список нефункциональных требований (время ответа, платформы, лимиты) | D14: Product Manager, Business Analyst | E14: 46013 | F14: 46014 | H14: 0 | I14: 14 | J14: 14 | K14: 0 | L14: Открыт | M14: Средний | N14: Требования и scope MVP | O14: 7 | P14: 0 | Q14: 0 | R14: 45994 | S14: Timur Byurchiev | T14: задача | U14: Frame Finder _ HW-5 | V14: 1
B15: 10 | C15: Зафиксировать список того, что не входит в MVP | D15: Product Manager, Business Analyst | E15: 46013 | F15: 46014 | H15: 0 | I15: 7.77 | J15: 7.77 | K15: 0 | L15: Открыт | M15: Средний | N15: Требования и scope MVP | O15: 7 | P15: 0 | Q15: 0 | R15: 45994 | S15: Timur Byurchiev | T15: задача | U15: Frame Finder _ HW-5 | V15: 1
B16: 11 | C16: Описать сценарий «распознать фильм по одному фото» в виде спецификации | D16: Product Manager, Business Analyst | E16: 46013 | F16: 46015 | H16: 0 | I16: 17.45 | J16: 17.45 | K16: 0 | L16: Открыт | M16: Средний | N16: Требования и scope MVP | O16: 7 | P16: 0 | Q16: 0 | R16: 45994 | S16: Timur Byurchiev | T16: задача | U16: Frame Finder _ HW-5 | V16: 1
B17: 12 | C17: Описать сценарии работы с лимитами free-tier и превышения лимита | D17: Product Manager, Business Analyst | E17: 46013 | F17: 46014 | H17: 0 | I17: 10.97 | J17: 10.97 | K17: 0 | L17: Открыт | M17: Средний | N17: Требования и scope MVP | O17: 7 | P17: 0 | Q17: 0 | R17: 45994 | S17: Timur Byurchiev | T17: задача | U17: Frame Finder _ HW-5 | V17: 1
B18: 13 | C18: Утвердить документ требований MVP внутри команды | D18: Product Manager | E18: 46015 | F18: 46016 | H18: 0 | I18: 12.57 | J18: 12.57 | K18: 0 | L18: Открыт | M18: Средний | N18: Требования и scope MVP | O18: 8, 9, 10, 11, 12 | P18: 0 | Q18: 0 | R18: 45994 | S18: Timur Byurchiev | T18: задача | U18: Frame Finder _ HW-5 | V18: 1
B19: 14 | C19: Определить пользовательские роли и ключевые сценарии использования | D19: Product Manager, UX Designer | E19: 46016 | F19: 46020 | H19: 0 | I19: 11.85 | J19: 11.85 | K19: 0 | L19: Открыт | M19: Средний | N19: UX/UI | O19: 13 | P19: 0 | Q19: 0 | R19: 45994 | S19: Timur Byurchiev | T19: задача | U19: Frame Finder _ HW-5 | V19: 1
B20: 15 | C20: Построить пользовательский поток распознавания фильма по фото | D20: UX Designer | E20: 46020 | F20: 46022 | H20: 0 | I20: 13.2 | J20: 13.2 | K20: 0 | L20: Открыт | M20: Средний | N20: UX/UI | O20: 14 | P20: 0 | Q20: 0 | R20: 45994 | S20: Timur Byurchiev | T20: задача | U20: Frame Finder _ HW-5 | V20: 1
B21: 16 | C21: Построить пользовательский поток просмотра истории запросов | D21: UX Designer | E21: 46020 | F21: 46021 | H21: 0 | I21: 9.45 | J21: 9.45 | K21: 0 | L21: Открыт | M21: Средний | N21: UX/UI | O21: 14 | P21: 0 | Q21: 0 | R21: 45994 | S21: Timur Byurchiev | T21: задача | U21: Frame Finder _ HW-5 | V21: 1
B22: 17 | C22: Спроектировать UX обработки ошибок (нет сети, плохое фото, фильм не найден) | D22: UX Designer | E22: 46020 | F22: 46022 | H22: 0 | I22: 12.4 | J22: 12.4 | K22: 0 | L22: Открыт | M22: Средний | N22: UX/UI | O22: 14 | P22: 0 | Q22: 0 | R22: 45994 | S22: Timur Byurchiev | T22: задача | U22: Frame Finder _ HW-5 | V22: 1
B23: 18 | C23: Подготовить wireframes стартового экрана и экрана загрузки фото | D23: UX Designer | E23: 46022 | F23: 46023 | H23: 0 | I23: 14 | J23: 14 | K23: 0 | L23: Открыт | M23: Средний | N23: UX/UI | O23: 15, 17 | P23: 0 | Q23: 0 | R23: 45994 | S23: Timur Byurchiev | T23: задача | U23: Frame Finder _ HW-5 | V23: 1
B24: 19 | C24: Подготовить wireframes экрана результата и экрана истории запросов | D24: UX Designer | E24: 46022 | F24: 46024 | H24: 0 | I24: 15.45 | J24: 15.45 | K24: 0 | L24: Открыт | M24: Средний | N24: UX/UI | O24: 15, 16, 17 | P24: 0 | Q24: 0 | R24: 45994 | S24: Timur Byurchiev | T24: задача | U24: Frame Finder _ HW-5 | V24: 1
B25: 20 | C25: Подготовить wireframes экрана логина/регистрации и экрана лимитов | D25: UX Designer | E25: 46022 | F25: 46023 | H25: 0 | I25: 14.17 | J25: 14.17 | K25: 0 | L25: Открыт | M25: Средний | N25: UX/UI | O25: 14, 17 | P25: 0 | Q25: 0 | R25: 45994 | S25: Timur Byurchiev | T25: задача | U25: Frame Finder _ HW-5 | V25: 1
B26: 21 | C26: Провести внутреннее UX-ревью и финализировать UX-спецификацию | D26: Product Manager, UX Designer | E26: 46024 | F26: 46027 | H26: 0 | I26: 13.6 | J26: 13.6 | K26: 0 | L26: Открыт | M26: Средний | N26: UX/UI | O26: 18, 19, 20 | P26: 0 | Q26: 0 | R26: 45994 | S26: Timur Byurchiev | T26: задача | U26: Frame Finder _ HW-5 | V26: 1
B27: 22 | C27: Определить технологический стек backend и БД | D27: Tech Lead | E27: 46016 | F27: 46020 | H27: 0 | I27: 10.25 | J27: 10.25 | K27: 0 | L27: Открыт | M27: Средний | N27: Архитектура и инфраструктура | O27: 13 | P27: 0 | Q27: 0 | R27: 45994 | S27: Timur Byurchiev | T27: задача | U27: Frame Finder _ HW-5 | V27: 1
B28: 23 | C28: Определить стек и способ развёртывания ML-сервиса (язык, фреймворк, тип API) | D28: Tech Lead, ML Engineer | E28: 46016 | F28: 46021 | H28: 0 | I28: 17.05 | J28: 17.05 | K28: 0 | L28: Открыт | M28: Средний | N28: Архитектура и инфраструктура | O28: 13 | P28: 0 | Q28: 0 | R28: 45994 | S28: Timur Byurchiev | T28: задача | U28: Frame Finder _ HW-5 | V28: 1
B29: 24 | C29: Спроектировать логическую архитектуру системы (mobile - backend - ML - БД - внешние сервисы) | D29: Tech Lead | E29: 46021 | F29: 46023 | H29: 0 | I29: 20.97 | J29: 20.97 | K29: 0 | L29: Открыт | M29: Средний | N29: Архитектура и инфраструктура | O29: 22, 23 | P29: 0 | Q29: 0 | R29: 45994 | S29: Timur Byurchiev | T29: задача | U29: Frame Finder _ HW-5 | V29: 1
B30: 25 | C30: Спроектировать модель данных и ER-диаграмму (фильмы, актёры, пользователи, запросы, лимиты) | D30: Tech Lead, Backend Developer | E30: 46023 | F30: 46028 | H30: 0 | I30: 21.37 | J30: 21.37 | K30: 0 | L30: Открыт | M30: Средний | N30: Архитектура и инфраструктура | O30: 24 | P30: 0 | Q30: 0 | R30: 45994 | S30: Timur Byurchiev | T30: задача | U30: Frame Finder _ HW-5 | V30: 1
B31: 26 | C31: Настроить репозитории и базовую структуру проектов (backend, mobile, ML) | D31: Backend Developer, DevOps Engineer | E31: 46023 | F31: 46027 | H31: 0 | I31: 13.37 | J31: 13.37 | K31: 0 | L31: Открыт | M31: Средний | N31: Архитектура и инфраструктура | O31: 24 | P31: 0 | Q31: 0 | R31: 45994 | S31: Timur Byurchiev | T31: задача | U31: Frame Finder _ HW-5 | V31: 1
B32: 27 | C32: Подготовить docker-compose для локального окружения backend, БД и заглушки ML | D32: DevOps Engineer | E32: 46027 | F32: 46029 | H32: 0 | I32: 15.2 | J32: 15.2 | K32: 0 | L32: Открыт | M32: Средний | N32: Архитектура и инфраструктура | O32: 26 | P32: 0 | Q32: 0 | R32: 45994 | S32: Timur Byurchiev | T32: задача | U32: Frame Finder _ HW-5 | V32: 1
B33: 28 | C33: Настроить CI-пайплайн для backend (сборка, тесты, линтер) | D33: Backend Developer, DevOps Engineer | E33: 46027 | F33: 46029 | H33: 0 | I33: 20.57 | J33: 20.57 | K33: 0 | L33: Открыт | M33: Средний | N33: Архитектура и инфраструктура | O33: 26 | P33: 0 | Q33: 0 | R33: 45994 | S33: Timur Byurchiev | T33: задача | U33: Frame Finder _ HW-5 | V33: 1
B34: 29 | C34: Настроить CI-пайплайн для Android-приложения (сборка, базовые проверки) | D34: DevOps Engineer, Mobile Dev | E34: 46027 | F34: 46029 | H34: 0 | I34: 17.37 | J34: 17.37 | K34: 0 | L34: Открыт | M34: Средний | N34: Архитектура и инфраструктура | O34: 26 | P34: 0 | Q34: 0 | R34: 45994 | S34: Timur Byurchiev | T34: задача | U34: Frame Finder _ HW-5 | V34: 1
B35: 30 | C35: Определить источники датасета и критерии отбора фильмов и кадров | D35: ML Engineer | E35: 46023 | F35: 46028 | H35: 0 | I35: 19.2 | J35: 19.2 | K35: 0 | L35: Открыт | M35: Средний | N35: ML и данные | O35: 23, 24 | P35: 0 | Q35: 0 | R35: 45994 | S35: Timur Byurchiev | T35: задача | U35: Frame Finder _ HW-5 | V35: 1
B36: 31 | C36: Спроектировать структуру хранения датасета и аннотаций (папки, форматы, схемы) | D36: ML Engineer | E36: 46028 | F36: 46030 | H36: 0 | I36: 16.25 | J36: 16.25 | K36: 0 | L36: Открыт | M36: Средний | N36: ML и данные | O36: 30 | P36: 0 | Q36: 0 | R36: 45994 | S36: Timur Byurchiev | T36: задача | U36: Frame Finder _ HW-5 | V36: 1
B37: 32 | C37: Реализовать скрипт загрузки изображений и метаданных из выбранных источников | D37: ML Engineer | E37: 46030 | F37: 46035 | H37: 0 | I37: 26.17 | J37: 26.17 | K37: 0 | L37: Открыт | M37: Средний | N37: ML и данные | O37: 31 | P37: 0 | Q37: 0 | R37: 45994 | S37: Timur Byurchiev | T37: задача | U37: Frame Finder _ HW-5 | V37: 1
B38: 33 | C38: Реализовать скрипт предобработки изображений (resize, нормализация и т.п.) | D38: ML Engineer | E38: 46035 | F38: 46037 | H38: 0 | I38: 15.77 | J38: 15.77 | K38: 0 | L38: Открыт | M38: Средний | N38: ML и данные | O38: 32 | P38: 0 | Q38: 0 | R38: 45994 | S38: Timur Byurchiev | T38: задача | U38: Frame Finder _ HW-5 | V38: 1
B39: 34 | C39: Разбить датасет на train / validation / test с фиксированными пропорциями | D39: ML Engineer | E39: 46035 | F39: 46036 | H39: 0 | I39: 10.57 | J39: 10.57 | K39: 0 | L39: Открыт | M39: Средний | N39: ML и данные | O39: 32 | P39: 0 | Q39: 0 | R39: 45994 | S39: Timur Byurchiev | T39: задача | U39: Frame Finder _ HW-5 | V39: 1
B40: 35 | C40: Провести исследование и сравнение кандидатных архитектур модели распознавания | D40: ML Engineer | E40: 46036 | F40: 46042 | H40: 0 | I40: 30.65 | J40: 30.65 | K40: 0 | L40: Открыт | M40: Средний | N40: ML и данные | O40: 34 | P40: 0 | Q40: 0 | R40: 45994 | S40: Timur Byurchiev | T40: задача | U40: Frame Finder _ HW-5 | V40: 1
B41: 36 | C41: Зафиксировать финальную архитектуру модели и требования к инференсу (формат I/O, latency) | D41: ML Engineer | E41: 46042 | F41: 46044 | H41: 0 | I41: 16 | J41: 16 | K41: 0 | L41: Открыт | M41: Средний | N41: ML и данные | O41: 35 | P41: 0 | Q41: 0 | R41: 45994 | S41: Timur Byurchiev | T41: задача | U41: Frame Finder _ HW-5 | V41: 1
B42: 37 | C42: Реализовать training-пайплайн для выбранной модели (конфиги, обучение, логирование метрик) | D42: ML Engineer | E42: 46044 | F42: 46050 | H42: 0 | I42: 30.17 | J42: 30.17 | K42: 0 | L42: Открыт | M42: Средний | N42: ML и данные | O42: 36 | P42: 0 | Q42: 0 | R42: 45994 | S42: Timur Byurchiev | T42: задача | U42: Frame Finder _ HW-5 | V42: 1
...
